from django import forms
from .models import User
from django.core.exceptions import ValidationError

class CustomAuthenticationForm(forms.Form):
    username = forms.CharField(max_length=150)
    password = forms.CharField(widget=forms.PasswordInput)
""" 
    def clean(self):
        cleaned_data = super().clean()
        username = cleaned_data.get('username')
        password = cleaned_data.get('password')

        return cleaned_data """

class UserForm(forms.ModelForm):
    class Meta:
        model = User
        fields = ['first_name', 'last_name',  'username', 'email', 'number_phone', 'internal_user']

    def save(self, commit=True):
        user = super().save(commit=False)
        user.is_active = False  # Establecer como inactivo por defecto
        if commit:
            user.save()
        return user
    
class SetPasswordForm(forms.Form):
    password = forms.CharField(widget=forms.PasswordInput)
    confirm_password = forms.CharField(widget=forms.PasswordInput)

    def clean(self):
        cleaned_data = super().clean()
        password = cleaned_data.get("password")
        confirm_password = cleaned_data.get("confirm_password")

        if password and confirm_password and password != confirm_password:
            raise ValidationError("Las contrase√±as no coinciden.")

        return cleaned_data
